Search space (old=query nodes; new=agent action space):
old: ['Index Only Scan' 'Index Scan' 'Seq Scan'] ['Hash Join' 'Nested Loop'] ['Hash' 'Hash Join' 'Index Only Scan' 'Index Scan' 'Memoize' 'Nested Loop'
 'Seq Scan' 'SimpleAggregate']
new: ['Index Only Scan' 'Index Scan' 'Seq Scan'] ['Hash Join' 'Merge Join' 'Nested Loop'] ['Hash' 'Hash Join' 'Index Only Scan' 'Index Scan' 'Memoize' 'Nested Loop'
 'Seq Scan' 'SimpleAggregate']
28c
28c
28c
28c
28c
28c
28c
28c
28c
28c
28c
28c
28c
28c
28c
28c
28c
28c
28c
28c
28c
28c
28c
28c
28c
28c
28c
28c
28c
28c
28c
28c
28c
28c
28c
28c
28c
28c
28c
28c
28c
28c
----------------------------------------
Exception happened during processing of request from ('127.0.0.1', 36972)
Traceback (most recent call last):
  File "/data1/wyz/miniconda3/envs/unlearning/lib/python3.8/socketserver.py", line 316, in _handle_request_noblock
    self.process_request(request, client_address)
  File "/data1/wyz/miniconda3/envs/unlearning/lib/python3.8/socketserver.py", line 347, in process_request
    self.finish_request(request, client_address)
  File "/data1/wyz/miniconda3/envs/unlearning/lib/python3.8/socketserver.py", line 360, in finish_request
    self.RequestHandlerClass(request, client_address, self)
  File "/data1/wyz/miniconda3/envs/unlearning/lib/python3.8/socketserver.py", line 747, in __init__
    self.handle()
  File "/data1/wyz/online/LEONForPostgres/leon_server.py", line 269, in handle
    if self.handle_json(json.loads(json_msg)):
  File "/data1/wyz/online/LEONForPostgres/leon_server.py", line 285, in handle_json
    result = self.server.leon_model.predict_plan(self.__messages)
  File "/data1/wyz/online/LEONForPostgres/leon_server.py", line 199, in predict_plan
    data[self.curr_file].append(all_time)
KeyError: '28c'
----------------------------------------
----------------------------------------
Exception happened during processing of request from ('127.0.0.1', 36984)
Traceback (most recent call last):
  File "/data1/wyz/miniconda3/envs/unlearning/lib/python3.8/socketserver.py", line 316, in _handle_request_noblock
    self.process_request(request, client_address)
  File "/data1/wyz/miniconda3/envs/unlearning/lib/python3.8/socketserver.py", line 347, in process_request
    self.finish_request(request, client_address)
  File "/data1/wyz/miniconda3/envs/unlearning/lib/python3.8/socketserver.py", line 360, in finish_request
    self.RequestHandlerClass(request, client_address, self)
  File "/data1/wyz/miniconda3/envs/unlearning/lib/python3.8/socketserver.py", line 747, in __init__
    self.handle()
  File "/data1/wyz/online/LEONForPostgres/leon_server.py", line 269, in handle
    if self.handle_json(json.loads(json_msg)):
  File "/data1/wyz/online/LEONForPostgres/leon_server.py", line 285, in handle_json
    result = self.server.leon_model.predict_plan(self.__messages)
  File "/data1/wyz/online/LEONForPostgres/leon_server.py", line 199, in predict_plan
    data[self.curr_file].append(all_time)
KeyError: '28c'
----------------------------------------
----------------------------------------
Exception happened during processing of request from ('127.0.0.1', 36998)
Traceback (most recent call last):
  File "/data1/wyz/miniconda3/envs/unlearning/lib/python3.8/socketserver.py", line 316, in _handle_request_noblock
    self.process_request(request, client_address)
  File "/data1/wyz/miniconda3/envs/unlearning/lib/python3.8/socketserver.py", line 347, in process_request
    self.finish_request(request, client_address)
  File "/data1/wyz/miniconda3/envs/unlearning/lib/python3.8/socketserver.py", line 360, in finish_request
    self.RequestHandlerClass(request, client_address, self)
  File "/data1/wyz/miniconda3/envs/unlearning/lib/python3.8/socketserver.py", line 747, in __init__
    self.handle()
  File "/data1/wyz/online/LEONForPostgres/leon_server.py", line 269, in handle
    if self.handle_json(json.loads(json_msg)):
  File "/data1/wyz/online/LEONForPostgres/leon_server.py", line 285, in handle_json
    result = self.server.leon_model.predict_plan(self.__messages)
  File "/data1/wyz/online/LEONForPostgres/leon_server.py", line 199, in predict_plan
    data[self.curr_file].append(all_time)
KeyError: '28c'
----------------------------------------
----------------------------------------
Exception happened during processing of request from ('127.0.0.1', 37010)
Traceback (most recent call last):
  File "/data1/wyz/miniconda3/envs/unlearning/lib/python3.8/socketserver.py", line 316, in _handle_request_noblock
    self.process_request(request, client_address)
  File "/data1/wyz/miniconda3/envs/unlearning/lib/python3.8/socketserver.py", line 347, in process_request
    self.finish_request(request, client_address)
  File "/data1/wyz/miniconda3/envs/unlearning/lib/python3.8/socketserver.py", line 360, in finish_request
    self.RequestHandlerClass(request, client_address, self)
  File "/data1/wyz/miniconda3/envs/unlearning/lib/python3.8/socketserver.py", line 747, in __init__
    self.handle()
  File "/data1/wyz/online/LEONForPostgres/leon_server.py", line 269, in handle
    if self.handle_json(json.loads(json_msg)):
  File "/data1/wyz/online/LEONForPostgres/leon_server.py", line 285, in handle_json
    result = self.server.leon_model.predict_plan(self.__messages)
  File "/data1/wyz/online/LEONForPostgres/leon_server.py", line 199, in predict_plan
    data[self.curr_file].append(all_time)
KeyError: '28c'
----------------------------------------
----------------------------------------
Exception happened during processing of request from ('127.0.0.1', 37016)
Traceback (most recent call last):
  File "/data1/wyz/miniconda3/envs/unlearning/lib/python3.8/socketserver.py", line 316, in _handle_request_noblock
    self.process_request(request, client_address)
  File "/data1/wyz/miniconda3/envs/unlearning/lib/python3.8/socketserver.py", line 347, in process_request
    self.finish_request(request, client_address)
  File "/data1/wyz/miniconda3/envs/unlearning/lib/python3.8/socketserver.py", line 360, in finish_request
    self.RequestHandlerClass(request, client_address, self)
  File "/data1/wyz/miniconda3/envs/unlearning/lib/python3.8/socketserver.py", line 747, in __init__
    self.handle()
  File "/data1/wyz/online/LEONForPostgres/leon_server.py", line 269, in handle
    if self.handle_json(json.loads(json_msg)):
  File "/data1/wyz/online/LEONForPostgres/leon_server.py", line 285, in handle_json
    result = self.server.leon_model.predict_plan(self.__messages)
  File "/data1/wyz/online/LEONForPostgres/leon_server.py", line 199, in predict_plan
    data[self.curr_file].append(all_time)
KeyError: '28c'
----------------------------------------
----------------------------------------
Exception happened during processing of request from ('127.0.0.1', 37028)
Traceback (most recent call last):
  File "/data1/wyz/miniconda3/envs/unlearning/lib/python3.8/socketserver.py", line 316, in _handle_request_noblock
    self.process_request(request, client_address)
  File "/data1/wyz/miniconda3/envs/unlearning/lib/python3.8/socketserver.py", line 347, in process_request
    self.finish_request(request, client_address)
  File "/data1/wyz/miniconda3/envs/unlearning/lib/python3.8/socketserver.py", line 360, in finish_request
    self.RequestHandlerClass(request, client_address, self)
  File "/data1/wyz/miniconda3/envs/unlearning/lib/python3.8/socketserver.py", line 747, in __init__
    self.handle()
  File "/data1/wyz/online/LEONForPostgres/leon_server.py", line 269, in handle
    if self.handle_json(json.loads(json_msg)):
  File "/data1/wyz/online/LEONForPostgres/leon_server.py", line 285, in handle_json
    result = self.server.leon_model.predict_plan(self.__messages)
  File "/data1/wyz/online/LEONForPostgres/leon_server.py", line 199, in predict_plan
    data[self.curr_file].append(all_time)
KeyError: '28c'
----------------------------------------
----------------------------------------
Exception happened during processing of request from ('127.0.0.1', 37030)
Traceback (most recent call last):
  File "/data1/wyz/miniconda3/envs/unlearning/lib/python3.8/socketserver.py", line 316, in _handle_request_noblock
    self.process_request(request, client_address)
  File "/data1/wyz/miniconda3/envs/unlearning/lib/python3.8/socketserver.py", line 347, in process_request
    self.finish_request(request, client_address)
  File "/data1/wyz/miniconda3/envs/unlearning/lib/python3.8/socketserver.py", line 360, in finish_request
    self.RequestHandlerClass(request, client_address, self)
  File "/data1/wyz/miniconda3/envs/unlearning/lib/python3.8/socketserver.py", line 747, in __init__
    self.handle()
  File "/data1/wyz/online/LEONForPostgres/leon_server.py", line 269, in handle
    if self.handle_json(json.loads(json_msg)):
  File "/data1/wyz/online/LEONForPostgres/leon_server.py", line 285, in handle_json
    result = self.server.leon_model.predict_plan(self.__messages)
  File "/data1/wyz/online/LEONForPostgres/leon_server.py", line 199, in predict_plan
    data[self.curr_file].append(all_time)
KeyError: '28c'
----------------------------------------
----------------------------------------
Exception happened during processing of request from ('127.0.0.1', 37034)
Traceback (most recent call last):
  File "/data1/wyz/miniconda3/envs/unlearning/lib/python3.8/socketserver.py", line 316, in _handle_request_noblock
    self.process_request(request, client_address)
  File "/data1/wyz/miniconda3/envs/unlearning/lib/python3.8/socketserver.py", line 347, in process_request
    self.finish_request(request, client_address)
  File "/data1/wyz/miniconda3/envs/unlearning/lib/python3.8/socketserver.py", line 360, in finish_request
    self.RequestHandlerClass(request, client_address, self)
  File "/data1/wyz/miniconda3/envs/unlearning/lib/python3.8/socketserver.py", line 747, in __init__
    self.handle()
  File "/data1/wyz/online/LEONForPostgres/leon_server.py", line 269, in handle
    if self.handle_json(json.loads(json_msg)):
  File "/data1/wyz/online/LEONForPostgres/leon_server.py", line 285, in handle_json
    result = self.server.leon_model.predict_plan(self.__messages)
  File "/data1/wyz/online/LEONForPostgres/leon_server.py", line 199, in predict_plan
    data[self.curr_file].append(all_time)
KeyError: '28c'
----------------------------------------
----------------------------------------
Exception happened during processing of request from ('127.0.0.1', 37042)
Traceback (most recent call last):
  File "/data1/wyz/miniconda3/envs/unlearning/lib/python3.8/socketserver.py", line 316, in _handle_request_noblock
    self.process_request(request, client_address)
  File "/data1/wyz/miniconda3/envs/unlearning/lib/python3.8/socketserver.py", line 347, in process_request
    self.finish_request(request, client_address)
  File "/data1/wyz/miniconda3/envs/unlearning/lib/python3.8/socketserver.py", line 360, in finish_request
    self.RequestHandlerClass(request, client_address, self)
  File "/data1/wyz/miniconda3/envs/unlearning/lib/python3.8/socketserver.py", line 747, in __init__
    self.handle()
  File "/data1/wyz/online/LEONForPostgres/leon_server.py", line 269, in handle
    if self.handle_json(json.loads(json_msg)):
  File "/data1/wyz/online/LEONForPostgres/leon_server.py", line 285, in handle_json
    result = self.server.leon_model.predict_plan(self.__messages)
  File "/data1/wyz/online/LEONForPostgres/leon_server.py", line 199, in predict_plan
    data[self.curr_file].append(all_time)
KeyError: '28c'
----------------------------------------
----------------------------------------
Exception happened during processing of request from ('127.0.0.1', 37054)
Traceback (most recent call last):
  File "/data1/wyz/miniconda3/envs/unlearning/lib/python3.8/socketserver.py", line 316, in _handle_request_noblock
    self.process_request(request, client_address)
  File "/data1/wyz/miniconda3/envs/unlearning/lib/python3.8/socketserver.py", line 347, in process_request
    self.finish_request(request, client_address)
  File "/data1/wyz/miniconda3/envs/unlearning/lib/python3.8/socketserver.py", line 360, in finish_request
    self.RequestHandlerClass(request, client_address, self)
  File "/data1/wyz/miniconda3/envs/unlearning/lib/python3.8/socketserver.py", line 747, in __init__
    self.handle()
  File "/data1/wyz/online/LEONForPostgres/leon_server.py", line 269, in handle
    if self.handle_json(json.loads(json_msg)):
  File "/data1/wyz/online/LEONForPostgres/leon_server.py", line 285, in handle_json
    result = self.server.leon_model.predict_plan(self.__messages)
  File "/data1/wyz/online/LEONForPostgres/leon_server.py", line 199, in predict_plan
    data[self.curr_file].append(all_time)
KeyError: '28c'
----------------------------------------
----------------------------------------
Exception happened during processing of request from ('127.0.0.1', 37058)
Traceback (most recent call last):
  File "/data1/wyz/miniconda3/envs/unlearning/lib/python3.8/socketserver.py", line 316, in _handle_request_noblock
    self.process_request(request, client_address)
  File "/data1/wyz/miniconda3/envs/unlearning/lib/python3.8/socketserver.py", line 347, in process_request
    self.finish_request(request, client_address)
  File "/data1/wyz/miniconda3/envs/unlearning/lib/python3.8/socketserver.py", line 360, in finish_request
    self.RequestHandlerClass(request, client_address, self)
  File "/data1/wyz/miniconda3/envs/unlearning/lib/python3.8/socketserver.py", line 747, in __init__
    self.handle()
  File "/data1/wyz/online/LEONForPostgres/leon_server.py", line 269, in handle
    if self.handle_json(json.loads(json_msg)):
  File "/data1/wyz/online/LEONForPostgres/leon_server.py", line 285, in handle_json
    result = self.server.leon_model.predict_plan(self.__messages)
  File "/data1/wyz/online/LEONForPostgres/leon_server.py", line 199, in predict_plan
    data[self.curr_file].append(all_time)
KeyError: '28c'
----------------------------------------
----------------------------------------
Exception happened during processing of request from ('127.0.0.1', 37060)
Traceback (most recent call last):
  File "/data1/wyz/miniconda3/envs/unlearning/lib/python3.8/socketserver.py", line 316, in _handle_request_noblock
    self.process_request(request, client_address)
  File "/data1/wyz/miniconda3/envs/unlearning/lib/python3.8/socketserver.py", line 347, in process_request
    self.finish_request(request, client_address)
  File "/data1/wyz/miniconda3/envs/unlearning/lib/python3.8/socketserver.py", line 360, in finish_request
    self.RequestHandlerClass(request, client_address, self)
  File "/data1/wyz/miniconda3/envs/unlearning/lib/python3.8/socketserver.py", line 747, in __init__
    self.handle()
  File "/data1/wyz/online/LEONForPostgres/leon_server.py", line 269, in handle
    if self.handle_json(json.loads(json_msg)):
  File "/data1/wyz/online/LEONForPostgres/leon_server.py", line 285, in handle_json
    result = self.server.leon_model.predict_plan(self.__messages)
  File "/data1/wyz/online/LEONForPostgres/leon_server.py", line 199, in predict_plan
    data[self.curr_file].append(all_time)
KeyError: '28c'
----------------------------------------
----------------------------------------
Exception happened during processing of request from ('127.0.0.1', 37066)
Traceback (most recent call last):
  File "/data1/wyz/miniconda3/envs/unlearning/lib/python3.8/socketserver.py", line 316, in _handle_request_noblock
    self.process_request(request, client_address)
  File "/data1/wyz/miniconda3/envs/unlearning/lib/python3.8/socketserver.py", line 347, in process_request
    self.finish_request(request, client_address)
  File "/data1/wyz/miniconda3/envs/unlearning/lib/python3.8/socketserver.py", line 360, in finish_request
    self.RequestHandlerClass(request, client_address, self)
  File "/data1/wyz/miniconda3/envs/unlearning/lib/python3.8/socketserver.py", line 747, in __init__
    self.handle()
  File "/data1/wyz/online/LEONForPostgres/leon_server.py", line 269, in handle
    if self.handle_json(json.loads(json_msg)):
  File "/data1/wyz/online/LEONForPostgres/leon_server.py", line 285, in handle_json
    result = self.server.leon_model.predict_plan(self.__messages)
  File "/data1/wyz/online/LEONForPostgres/leon_server.py", line 199, in predict_plan
    data[self.curr_file].append(all_time)
KeyError: '28c'
----------------------------------------
----------------------------------------
Exception happened during processing of request from ('127.0.0.1', 37082)
Traceback (most recent call last):
  File "/data1/wyz/miniconda3/envs/unlearning/lib/python3.8/socketserver.py", line 316, in _handle_request_noblock
    self.process_request(request, client_address)
  File "/data1/wyz/miniconda3/envs/unlearning/lib/python3.8/socketserver.py", line 347, in process_request
    self.finish_request(request, client_address)
  File "/data1/wyz/miniconda3/envs/unlearning/lib/python3.8/socketserver.py", line 360, in finish_request
    self.RequestHandlerClass(request, client_address, self)
  File "/data1/wyz/miniconda3/envs/unlearning/lib/python3.8/socketserver.py", line 747, in __init__
    self.handle()
  File "/data1/wyz/online/LEONForPostgres/leon_server.py", line 269, in handle
    if self.handle_json(json.loads(json_msg)):
  File "/data1/wyz/online/LEONForPostgres/leon_server.py", line 285, in handle_json
    result = self.server.leon_model.predict_plan(self.__messages)
  File "/data1/wyz/online/LEONForPostgres/leon_server.py", line 199, in predict_plan
    data[self.curr_file].append(all_time)
KeyError: '28c'
----------------------------------------
28c
28c
28c
28c
28c
28c
28c
28c
28c
28c
28c
28c
28c
28c
28c
28c
28c
28c
28c
28c
28c
28c
28c
28c
28c
28c
28c
28c
Process Process-1:
Traceback (most recent call last):
  File "/data1/wyz/miniconda3/envs/unlearning/lib/python3.8/multiprocessing/process.py", line 315, in _bootstrap
    self.run()
  File "/data1/wyz/miniconda3/envs/unlearning/lib/python3.8/multiprocessing/process.py", line 108, in run
    self._target(*self._args, **self._kwargs)
  File "/data1/wyz/online/LEONForPostgres/leon_server.py", line 307, in start_server
    server.serve_forever()
  File "/data1/wyz/miniconda3/envs/unlearning/lib/python3.8/socketserver.py", line 232, in serve_forever
    ready = selector.select(poll_interval)
  File "/data1/wyz/miniconda3/envs/unlearning/lib/python3.8/selectors.py", line 415, in select
    fd_event_list = self._selector.poll(timeout)
