Search space (old=query nodes; new=agent action space):
old: ['Index Only Scan' 'Index Scan' 'Seq Scan'] ['Hash Join' 'Nested Loop'] ['Hash' 'Hash Join' 'Index Only Scan' 'Index Scan' 'Memoize' 'Nested Loop'
 'Seq Scan' 'SimpleAggregate']
new: ['Index Only Scan' 'Index Scan' 'Seq Scan'] ['Hash Join' 'Merge Join' 'Nested Loop'] ['Hash' 'Hash Join' 'Index Only Scan' 'Index Scan' 'Memoize' 'Nested Loop'
 'Seq Scan' 'SimpleAggregate']
----------------------------------------
Exception happened during processing of request from ('127.0.0.1', 51360)
Traceback (most recent call last):
  File "/data1/wyz/miniconda3/envs/unlearning/lib/python3.8/socketserver.py", line 316, in _handle_request_noblock
    self.process_request(request, client_address)
  File "/data1/wyz/miniconda3/envs/unlearning/lib/python3.8/socketserver.py", line 347, in process_request
    self.finish_request(request, client_address)
  File "/data1/wyz/miniconda3/envs/unlearning/lib/python3.8/socketserver.py", line 360, in finish_request
    self.RequestHandlerClass(request, client_address, self)
  File "/data1/wyz/miniconda3/envs/unlearning/lib/python3.8/socketserver.py", line 747, in __init__
    self.handle()
  File "/data1/wyz/online/LEONForPostgres/leon_server.py", line 269, in handle
    if self.handle_json(json.loads(json_msg)):
  File "/data1/wyz/online/LEONForPostgres/leon_server.py", line 285, in handle_json
    result = self.server.leon_model.predict_plan(self.__messages)
  File "/data1/wyz/online/LEONForPostgres/leon_server.py", line 199, in predict_plan
    data[self.curr_file].append(all_time)
KeyError: '33c'
----------------------------------------
----------------------------------------
Exception happened during processing of request from ('127.0.0.1', 51370)
Traceback (most recent call last):
  File "/data1/wyz/miniconda3/envs/unlearning/lib/python3.8/socketserver.py", line 316, in _handle_request_noblock
    self.process_request(request, client_address)
  File "/data1/wyz/miniconda3/envs/unlearning/lib/python3.8/socketserver.py", line 347, in process_request
    self.finish_request(request, client_address)
  File "/data1/wyz/miniconda3/envs/unlearning/lib/python3.8/socketserver.py", line 360, in finish_request
    self.RequestHandlerClass(request, client_address, self)
  File "/data1/wyz/miniconda3/envs/unlearning/lib/python3.8/socketserver.py", line 747, in __init__
    self.handle()
  File "/data1/wyz/online/LEONForPostgres/leon_server.py", line 269, in handle
    if self.handle_json(json.loads(json_msg)):
  File "/data1/wyz/online/LEONForPostgres/leon_server.py", line 285, in handle_json
    result = self.server.leon_model.predict_plan(self.__messages)
  File "/data1/wyz/online/LEONForPostgres/leon_server.py", line 199, in predict_plan
    data[self.curr_file].append(all_time)
KeyError: '33c'
----------------------------------------
----------------------------------------
Exception happened during processing of request from ('127.0.0.1', 51380)
Traceback (most recent call last):
  File "/data1/wyz/miniconda3/envs/unlearning/lib/python3.8/socketserver.py", line 316, in _handle_request_noblock
    self.process_request(request, client_address)
  File "/data1/wyz/miniconda3/envs/unlearning/lib/python3.8/socketserver.py", line 347, in process_request
    self.finish_request(request, client_address)
  File "/data1/wyz/miniconda3/envs/unlearning/lib/python3.8/socketserver.py", line 360, in finish_request
    self.RequestHandlerClass(request, client_address, self)
  File "/data1/wyz/miniconda3/envs/unlearning/lib/python3.8/socketserver.py", line 747, in __init__
    self.handle()
  File "/data1/wyz/online/LEONForPostgres/leon_server.py", line 269, in handle
    if self.handle_json(json.loads(json_msg)):
  File "/data1/wyz/online/LEONForPostgres/leon_server.py", line 285, in handle_json
    result = self.server.leon_model.predict_plan(self.__messages)
  File "/data1/wyz/online/LEONForPostgres/leon_server.py", line 199, in predict_plan
    data[self.curr_file].append(all_time)
KeyError: '33c'
----------------------------------------
----------------------------------------
Exception happened during processing of request from ('127.0.0.1', 51390)
Traceback (most recent call last):
  File "/data1/wyz/miniconda3/envs/unlearning/lib/python3.8/socketserver.py", line 316, in _handle_request_noblock
    self.process_request(request, client_address)
  File "/data1/wyz/miniconda3/envs/unlearning/lib/python3.8/socketserver.py", line 347, in process_request
    self.finish_request(request, client_address)
  File "/data1/wyz/miniconda3/envs/unlearning/lib/python3.8/socketserver.py", line 360, in finish_request
    self.RequestHandlerClass(request, client_address, self)
  File "/data1/wyz/miniconda3/envs/unlearning/lib/python3.8/socketserver.py", line 747, in __init__
    self.handle()
  File "/data1/wyz/online/LEONForPostgres/leon_server.py", line 269, in handle
    if self.handle_json(json.loads(json_msg)):
  File "/data1/wyz/online/LEONForPostgres/leon_server.py", line 285, in handle_json
    result = self.server.leon_model.predict_plan(self.__messages)
  File "/data1/wyz/online/LEONForPostgres/leon_server.py", line 199, in predict_plan
    data[self.curr_file].append(all_time)
KeyError: '33c'
----------------------------------------
----------------------------------------
Exception happened during processing of request from ('127.0.0.1', 51402)
Traceback (most recent call last):
  File "/data1/wyz/miniconda3/envs/unlearning/lib/python3.8/socketserver.py", line 316, in _handle_request_noblock
    self.process_request(request, client_address)
  File "/data1/wyz/miniconda3/envs/unlearning/lib/python3.8/socketserver.py", line 347, in process_request
    self.finish_request(request, client_address)
  File "/data1/wyz/miniconda3/envs/unlearning/lib/python3.8/socketserver.py", line 360, in finish_request
    self.RequestHandlerClass(request, client_address, self)
  File "/data1/wyz/miniconda3/envs/unlearning/lib/python3.8/socketserver.py", line 747, in __init__
    self.handle()
  File "/data1/wyz/online/LEONForPostgres/leon_server.py", line 269, in handle
    if self.handle_json(json.loads(json_msg)):
  File "/data1/wyz/online/LEONForPostgres/leon_server.py", line 285, in handle_json
    result = self.server.leon_model.predict_plan(self.__messages)
  File "/data1/wyz/online/LEONForPostgres/leon_server.py", line 199, in predict_plan
    data[self.curr_file].append(all_time)
KeyError: '33c'
----------------------------------------
----------------------------------------
Exception happened during processing of request from ('127.0.0.1', 51416)
Traceback (most recent call last):
  File "/data1/wyz/miniconda3/envs/unlearning/lib/python3.8/socketserver.py", line 316, in _handle_request_noblock
    self.process_request(request, client_address)
  File "/data1/wyz/miniconda3/envs/unlearning/lib/python3.8/socketserver.py", line 347, in process_request
    self.finish_request(request, client_address)
  File "/data1/wyz/miniconda3/envs/unlearning/lib/python3.8/socketserver.py", line 360, in finish_request
    self.RequestHandlerClass(request, client_address, self)
  File "/data1/wyz/miniconda3/envs/unlearning/lib/python3.8/socketserver.py", line 747, in __init__
    self.handle()
  File "/data1/wyz/online/LEONForPostgres/leon_server.py", line 269, in handle
    if self.handle_json(json.loads(json_msg)):
  File "/data1/wyz/online/LEONForPostgres/leon_server.py", line 285, in handle_json
    result = self.server.leon_model.predict_plan(self.__messages)
  File "/data1/wyz/online/LEONForPostgres/leon_server.py", line 199, in predict_plan
    data[self.curr_file].append(all_time)
KeyError: '33c'
----------------------------------------
----------------------------------------
Exception happened during processing of request from ('127.0.0.1', 51430)
Traceback (most recent call last):
  File "/data1/wyz/miniconda3/envs/unlearning/lib/python3.8/socketserver.py", line 316, in _handle_request_noblock
    self.process_request(request, client_address)
  File "/data1/wyz/miniconda3/envs/unlearning/lib/python3.8/socketserver.py", line 347, in process_request
    self.finish_request(request, client_address)
  File "/data1/wyz/miniconda3/envs/unlearning/lib/python3.8/socketserver.py", line 360, in finish_request
    self.RequestHandlerClass(request, client_address, self)
  File "/data1/wyz/miniconda3/envs/unlearning/lib/python3.8/socketserver.py", line 747, in __init__
    self.handle()
  File "/data1/wyz/online/LEONForPostgres/leon_server.py", line 269, in handle
    if self.handle_json(json.loads(json_msg)):
  File "/data1/wyz/online/LEONForPostgres/leon_server.py", line 285, in handle_json
    result = self.server.leon_model.predict_plan(self.__messages)
  File "/data1/wyz/online/LEONForPostgres/leon_server.py", line 199, in predict_plan
    data[self.curr_file].append(all_time)
KeyError: '33c'
----------------------------------------
----------------------------------------
Exception happened during processing of request from ('127.0.0.1', 51446)
Traceback (most recent call last):
  File "/data1/wyz/miniconda3/envs/unlearning/lib/python3.8/socketserver.py", line 316, in _handle_request_noblock
    self.process_request(request, client_address)
  File "/data1/wyz/miniconda3/envs/unlearning/lib/python3.8/socketserver.py", line 347, in process_request
    self.finish_request(request, client_address)
  File "/data1/wyz/miniconda3/envs/unlearning/lib/python3.8/socketserver.py", line 360, in finish_request
    self.RequestHandlerClass(request, client_address, self)
  File "/data1/wyz/miniconda3/envs/unlearning/lib/python3.8/socketserver.py", line 747, in __init__
    self.handle()
  File "/data1/wyz/online/LEONForPostgres/leon_server.py", line 269, in handle
    if self.handle_json(json.loads(json_msg)):
  File "/data1/wyz/online/LEONForPostgres/leon_server.py", line 285, in handle_json
    result = self.server.leon_model.predict_plan(self.__messages)
  File "/data1/wyz/online/LEONForPostgres/leon_server.py", line 199, in predict_plan
    data[self.curr_file].append(all_time)
KeyError: '33c'
----------------------------------------
----------------------------------------
Exception happened during processing of request from ('127.0.0.1', 51462)
Traceback (most recent call last):
  File "/data1/wyz/miniconda3/envs/unlearning/lib/python3.8/socketserver.py", line 316, in _handle_request_noblock
    self.process_request(request, client_address)
  File "/data1/wyz/miniconda3/envs/unlearning/lib/python3.8/socketserver.py", line 347, in process_request
    self.finish_request(request, client_address)
  File "/data1/wyz/miniconda3/envs/unlearning/lib/python3.8/socketserver.py", line 360, in finish_request
    self.RequestHandlerClass(request, client_address, self)
  File "/data1/wyz/miniconda3/envs/unlearning/lib/python3.8/socketserver.py", line 747, in __init__
    self.handle()
  File "/data1/wyz/online/LEONForPostgres/leon_server.py", line 269, in handle
    if self.handle_json(json.loads(json_msg)):
  File "/data1/wyz/online/LEONForPostgres/leon_server.py", line 285, in handle_json
    result = self.server.leon_model.predict_plan(self.__messages)
  File "/data1/wyz/online/LEONForPostgres/leon_server.py", line 199, in predict_plan
    data[self.curr_file].append(all_time)
KeyError: '33c'
----------------------------------------
----------------------------------------
Exception happened during processing of request from ('127.0.0.1', 51472)
Traceback (most recent call last):
  File "/data1/wyz/miniconda3/envs/unlearning/lib/python3.8/socketserver.py", line 316, in _handle_request_noblock
    self.process_request(request, client_address)
  File "/data1/wyz/miniconda3/envs/unlearning/lib/python3.8/socketserver.py", line 347, in process_request
    self.finish_request(request, client_address)
  File "/data1/wyz/miniconda3/envs/unlearning/lib/python3.8/socketserver.py", line 360, in finish_request
    self.RequestHandlerClass(request, client_address, self)
  File "/data1/wyz/miniconda3/envs/unlearning/lib/python3.8/socketserver.py", line 747, in __init__
    self.handle()
  File "/data1/wyz/online/LEONForPostgres/leon_server.py", line 269, in handle
    if self.handle_json(json.loads(json_msg)):
  File "/data1/wyz/online/LEONForPostgres/leon_server.py", line 285, in handle_json
    result = self.server.leon_model.predict_plan(self.__messages)
  File "/data1/wyz/online/LEONForPostgres/leon_server.py", line 199, in predict_plan
    data[self.curr_file].append(all_time)
KeyError: '33c'
----------------------------------------
----------------------------------------
Exception happened during processing of request from ('127.0.0.1', 51476)
Traceback (most recent call last):
  File "/data1/wyz/miniconda3/envs/unlearning/lib/python3.8/socketserver.py", line 316, in _handle_request_noblock
    self.process_request(request, client_address)
  File "/data1/wyz/miniconda3/envs/unlearning/lib/python3.8/socketserver.py", line 347, in process_request
    self.finish_request(request, client_address)
  File "/data1/wyz/miniconda3/envs/unlearning/lib/python3.8/socketserver.py", line 360, in finish_request
    self.RequestHandlerClass(request, client_address, self)
  File "/data1/wyz/miniconda3/envs/unlearning/lib/python3.8/socketserver.py", line 747, in __init__
    self.handle()
  File "/data1/wyz/online/LEONForPostgres/leon_server.py", line 269, in handle
    if self.handle_json(json.loads(json_msg)):
  File "/data1/wyz/online/LEONForPostgres/leon_server.py", line 285, in handle_json
    result = self.server.leon_model.predict_plan(self.__messages)
  File "/data1/wyz/online/LEONForPostgres/leon_server.py", line 199, in predict_plan
    data[self.curr_file].append(all_time)
KeyError: '33c'
----------------------------------------
----------------------------------------
Exception happened during processing of request from ('127.0.0.1', 51488)
Traceback (most recent call last):
  File "/data1/wyz/miniconda3/envs/unlearning/lib/python3.8/socketserver.py", line 316, in _handle_request_noblock
    self.process_request(request, client_address)
  File "/data1/wyz/miniconda3/envs/unlearning/lib/python3.8/socketserver.py", line 347, in process_request
    self.finish_request(request, client_address)
  File "/data1/wyz/miniconda3/envs/unlearning/lib/python3.8/socketserver.py", line 360, in finish_request
    self.RequestHandlerClass(request, client_address, self)
  File "/data1/wyz/miniconda3/envs/unlearning/lib/python3.8/socketserver.py", line 747, in __init__
    self.handle()
  File "/data1/wyz/online/LEONForPostgres/leon_server.py", line 269, in handle
    if self.handle_json(json.loads(json_msg)):
  File "/data1/wyz/online/LEONForPostgres/leon_server.py", line 285, in handle_json
    result = self.server.leon_model.predict_plan(self.__messages)
  File "/data1/wyz/online/LEONForPostgres/leon_server.py", line 199, in predict_plan
    data[self.curr_file].append(all_time)
KeyError: '33c'
----------------------------------------
----------------------------------------
Exception happened during processing of request from ('127.0.0.1', 51490)
Traceback (most recent call last):
  File "/data1/wyz/miniconda3/envs/unlearning/lib/python3.8/socketserver.py", line 316, in _handle_request_noblock
    self.process_request(request, client_address)
  File "/data1/wyz/miniconda3/envs/unlearning/lib/python3.8/socketserver.py", line 347, in process_request
    self.finish_request(request, client_address)
  File "/data1/wyz/miniconda3/envs/unlearning/lib/python3.8/socketserver.py", line 360, in finish_request
    self.RequestHandlerClass(request, client_address, self)
  File "/data1/wyz/miniconda3/envs/unlearning/lib/python3.8/socketserver.py", line 747, in __init__
    self.handle()
  File "/data1/wyz/online/LEONForPostgres/leon_server.py", line 269, in handle
    if self.handle_json(json.loads(json_msg)):
  File "/data1/wyz/online/LEONForPostgres/leon_server.py", line 285, in handle_json
    result = self.server.leon_model.predict_plan(self.__messages)
  File "/data1/wyz/online/LEONForPostgres/leon_server.py", line 199, in predict_plan
    data[self.curr_file].append(all_time)
KeyError: '33c'
----------------------------------------
----------------------------------------
Exception happened during processing of request from ('127.0.0.1', 51494)
Traceback (most recent call last):
  File "/data1/wyz/miniconda3/envs/unlearning/lib/python3.8/socketserver.py", line 316, in _handle_request_noblock
    self.process_request(request, client_address)
  File "/data1/wyz/miniconda3/envs/unlearning/lib/python3.8/socketserver.py", line 347, in process_request
    self.finish_request(request, client_address)
  File "/data1/wyz/miniconda3/envs/unlearning/lib/python3.8/socketserver.py", line 360, in finish_request
    self.RequestHandlerClass(request, client_address, self)
  File "/data1/wyz/miniconda3/envs/unlearning/lib/python3.8/socketserver.py", line 747, in __init__
    self.handle()
  File "/data1/wyz/online/LEONForPostgres/leon_server.py", line 269, in handle
    if self.handle_json(json.loads(json_msg)):
  File "/data1/wyz/online/LEONForPostgres/leon_server.py", line 285, in handle_json
    result = self.server.leon_model.predict_plan(self.__messages)
  File "/data1/wyz/online/LEONForPostgres/leon_server.py", line 199, in predict_plan
    data[self.curr_file].append(all_time)
KeyError: '33c'
----------------------------------------
----------------------------------------
Exception happened during processing of request from ('127.0.0.1', 51502)
Traceback (most recent call last):
  File "/data1/wyz/miniconda3/envs/unlearning/lib/python3.8/socketserver.py", line 316, in _handle_request_noblock
    self.process_request(request, client_address)
  File "/data1/wyz/miniconda3/envs/unlearning/lib/python3.8/socketserver.py", line 347, in process_request
    self.finish_request(request, client_address)
  File "/data1/wyz/miniconda3/envs/unlearning/lib/python3.8/socketserver.py", line 360, in finish_request
    self.RequestHandlerClass(request, client_address, self)
  File "/data1/wyz/miniconda3/envs/unlearning/lib/python3.8/socketserver.py", line 747, in __init__
    self.handle()
  File "/data1/wyz/online/LEONForPostgres/leon_server.py", line 269, in handle
    if self.handle_json(json.loads(json_msg)):
  File "/data1/wyz/online/LEONForPostgres/leon_server.py", line 285, in handle_json
    result = self.server.leon_model.predict_plan(self.__messages)
  File "/data1/wyz/online/LEONForPostgres/leon_server.py", line 199, in predict_plan
    data[self.curr_file].append(all_time)
KeyError: '33c'
----------------------------------------
----------------------------------------
Exception happened during processing of request from ('127.0.0.1', 51508)
Traceback (most recent call last):
  File "/data1/wyz/miniconda3/envs/unlearning/lib/python3.8/socketserver.py", line 316, in _handle_request_noblock
    self.process_request(request, client_address)
  File "/data1/wyz/miniconda3/envs/unlearning/lib/python3.8/socketserver.py", line 347, in process_request
    self.finish_request(request, client_address)
  File "/data1/wyz/miniconda3/envs/unlearning/lib/python3.8/socketserver.py", line 360, in finish_request
    self.RequestHandlerClass(request, client_address, self)
  File "/data1/wyz/miniconda3/envs/unlearning/lib/python3.8/socketserver.py", line 747, in __init__
    self.handle()
  File "/data1/wyz/online/LEONForPostgres/leon_server.py", line 269, in handle
    if self.handle_json(json.loads(json_msg)):
  File "/data1/wyz/online/LEONForPostgres/leon_server.py", line 285, in handle_json
    result = self.server.leon_model.predict_plan(self.__messages)
  File "/data1/wyz/online/LEONForPostgres/leon_server.py", line 199, in predict_plan
    data[self.curr_file].append(all_time)
KeyError: '33c'
----------------------------------------
----------------------------------------
Exception happened during processing of request from ('127.0.0.1', 51518)
Traceback (most recent call last):
  File "/data1/wyz/miniconda3/envs/unlearning/lib/python3.8/socketserver.py", line 316, in _handle_request_noblock
    self.process_request(request, client_address)
  File "/data1/wyz/miniconda3/envs/unlearning/lib/python3.8/socketserver.py", line 347, in process_request
    self.finish_request(request, client_address)
  File "/data1/wyz/miniconda3/envs/unlearning/lib/python3.8/socketserver.py", line 360, in finish_request
    self.RequestHandlerClass(request, client_address, self)
  File "/data1/wyz/miniconda3/envs/unlearning/lib/python3.8/socketserver.py", line 747, in __init__
    self.handle()
  File "/data1/wyz/online/LEONForPostgres/leon_server.py", line 269, in handle
    if self.handle_json(json.loads(json_msg)):
  File "/data1/wyz/online/LEONForPostgres/leon_server.py", line 285, in handle_json
    result = self.server.leon_model.predict_plan(self.__messages)
  File "/data1/wyz/online/LEONForPostgres/leon_server.py", line 199, in predict_plan
    data[self.curr_file].append(all_time)
KeyError: '33c'
----------------------------------------
----------------------------------------
Exception happened during processing of request from ('127.0.0.1', 51530)
Traceback (most recent call last):
  File "/data1/wyz/miniconda3/envs/unlearning/lib/python3.8/socketserver.py", line 316, in _handle_request_noblock
    self.process_request(request, client_address)
  File "/data1/wyz/miniconda3/envs/unlearning/lib/python3.8/socketserver.py", line 347, in process_request
    self.finish_request(request, client_address)
  File "/data1/wyz/miniconda3/envs/unlearning/lib/python3.8/socketserver.py", line 360, in finish_request
    self.RequestHandlerClass(request, client_address, self)
  File "/data1/wyz/miniconda3/envs/unlearning/lib/python3.8/socketserver.py", line 747, in __init__
    self.handle()
  File "/data1/wyz/online/LEONForPostgres/leon_server.py", line 269, in handle
    if self.handle_json(json.loads(json_msg)):
  File "/data1/wyz/online/LEONForPostgres/leon_server.py", line 285, in handle_json
    result = self.server.leon_model.predict_plan(self.__messages)
  File "/data1/wyz/online/LEONForPostgres/leon_server.py", line 199, in predict_plan
    data[self.curr_file].append(all_time)
KeyError: '33c'
----------------------------------------
----------------------------------------
Exception happened during processing of request from ('127.0.0.1', 51532)
Traceback (most recent call last):
  File "/data1/wyz/miniconda3/envs/unlearning/lib/python3.8/socketserver.py", line 316, in _handle_request_noblock
    self.process_request(request, client_address)
  File "/data1/wyz/miniconda3/envs/unlearning/lib/python3.8/socketserver.py", line 347, in process_request
    self.finish_request(request, client_address)
  File "/data1/wyz/miniconda3/envs/unlearning/lib/python3.8/socketserver.py", line 360, in finish_request
    self.RequestHandlerClass(request, client_address, self)
  File "/data1/wyz/miniconda3/envs/unlearning/lib/python3.8/socketserver.py", line 747, in __init__
    self.handle()
  File "/data1/wyz/online/LEONForPostgres/leon_server.py", line 269, in handle
    if self.handle_json(json.loads(json_msg)):
  File "/data1/wyz/online/LEONForPostgres/leon_server.py", line 285, in handle_json
    result = self.server.leon_model.predict_plan(self.__messages)
  File "/data1/wyz/online/LEONForPostgres/leon_server.py", line 199, in predict_plan
    data[self.curr_file].append(all_time)
KeyError: '33c'
----------------------------------------
----------------------------------------
Exception happened during processing of request from ('127.0.0.1', 51536)
Traceback (most recent call last):
  File "/data1/wyz/miniconda3/envs/unlearning/lib/python3.8/socketserver.py", line 316, in _handle_request_noblock
    self.process_request(request, client_address)
  File "/data1/wyz/miniconda3/envs/unlearning/lib/python3.8/socketserver.py", line 347, in process_request
    self.finish_request(request, client_address)
  File "/data1/wyz/miniconda3/envs/unlearning/lib/python3.8/socketserver.py", line 360, in finish_request
    self.RequestHandlerClass(request, client_address, self)
  File "/data1/wyz/miniconda3/envs/unlearning/lib/python3.8/socketserver.py", line 747, in __init__
    self.handle()
  File "/data1/wyz/online/LEONForPostgres/leon_server.py", line 269, in handle
    if self.handle_json(json.loads(json_msg)):
  File "/data1/wyz/online/LEONForPostgres/leon_server.py", line 285, in handle_json
    result = self.server.leon_model.predict_plan(self.__messages)
  File "/data1/wyz/online/LEONForPostgres/leon_server.py", line 199, in predict_plan
    data[self.curr_file].append(all_time)
KeyError: '33c'
----------------------------------------
----------------------------------------
Exception happened during processing of request from ('127.0.0.1', 51552)
Traceback (most recent call last):
  File "/data1/wyz/miniconda3/envs/unlearning/lib/python3.8/socketserver.py", line 316, in _handle_request_noblock
    self.process_request(request, client_address)
  File "/data1/wyz/miniconda3/envs/unlearning/lib/python3.8/socketserver.py", line 347, in process_request
    self.finish_request(request, client_address)
  File "/data1/wyz/miniconda3/envs/unlearning/lib/python3.8/socketserver.py", line 360, in finish_request
    self.RequestHandlerClass(request, client_address, self)
  File "/data1/wyz/miniconda3/envs/unlearning/lib/python3.8/socketserver.py", line 747, in __init__
    self.handle()
  File "/data1/wyz/online/LEONForPostgres/leon_server.py", line 269, in handle
    if self.handle_json(json.loads(json_msg)):
  File "/data1/wyz/online/LEONForPostgres/leon_server.py", line 285, in handle_json
    result = self.server.leon_model.predict_plan(self.__messages)
  File "/data1/wyz/online/LEONForPostgres/leon_server.py", line 199, in predict_plan
    data[self.curr_file].append(all_time)
KeyError: '33c'
----------------------------------------
----------------------------------------
Exception happened during processing of request from ('127.0.0.1', 51560)
Traceback (most recent call last):
  File "/data1/wyz/miniconda3/envs/unlearning/lib/python3.8/socketserver.py", line 316, in _handle_request_noblock
    self.process_request(request, client_address)
  File "/data1/wyz/miniconda3/envs/unlearning/lib/python3.8/socketserver.py", line 347, in process_request
    self.finish_request(request, client_address)
  File "/data1/wyz/miniconda3/envs/unlearning/lib/python3.8/socketserver.py", line 360, in finish_request
    self.RequestHandlerClass(request, client_address, self)
  File "/data1/wyz/miniconda3/envs/unlearning/lib/python3.8/socketserver.py", line 747, in __init__
    self.handle()
  File "/data1/wyz/online/LEONForPostgres/leon_server.py", line 269, in handle
    if self.handle_json(json.loads(json_msg)):
  File "/data1/wyz/online/LEONForPostgres/leon_server.py", line 285, in handle_json
    result = self.server.leon_model.predict_plan(self.__messages)
  File "/data1/wyz/online/LEONForPostgres/leon_server.py", line 199, in predict_plan
    data[self.curr_file].append(all_time)
KeyError: '33c'
----------------------------------------
----------------------------------------
Exception happened during processing of request from ('127.0.0.1', 51562)
Traceback (most recent call last):
  File "/data1/wyz/miniconda3/envs/unlearning/lib/python3.8/socketserver.py", line 316, in _handle_request_noblock
    self.process_request(request, client_address)
  File "/data1/wyz/miniconda3/envs/unlearning/lib/python3.8/socketserver.py", line 347, in process_request
    self.finish_request(request, client_address)
  File "/data1/wyz/miniconda3/envs/unlearning/lib/python3.8/socketserver.py", line 360, in finish_request
    self.RequestHandlerClass(request, client_address, self)
  File "/data1/wyz/miniconda3/envs/unlearning/lib/python3.8/socketserver.py", line 747, in __init__
    self.handle()
  File "/data1/wyz/online/LEONForPostgres/leon_server.py", line 269, in handle
    if self.handle_json(json.loads(json_msg)):
  File "/data1/wyz/online/LEONForPostgres/leon_server.py", line 285, in handle_json
    result = self.server.leon_model.predict_plan(self.__messages)
  File "/data1/wyz/online/LEONForPostgres/leon_server.py", line 199, in predict_plan
    data[self.curr_file].append(all_time)
KeyError: '33c'
----------------------------------------
----------------------------------------
Exception happened during processing of request from ('127.0.0.1', 51578)
Traceback (most recent call last):
  File "/data1/wyz/miniconda3/envs/unlearning/lib/python3.8/socketserver.py", line 316, in _handle_request_noblock
    self.process_request(request, client_address)
  File "/data1/wyz/miniconda3/envs/unlearning/lib/python3.8/socketserver.py", line 347, in process_request
    self.finish_request(request, client_address)
  File "/data1/wyz/miniconda3/envs/unlearning/lib/python3.8/socketserver.py", line 360, in finish_request
    self.RequestHandlerClass(request, client_address, self)
  File "/data1/wyz/miniconda3/envs/unlearning/lib/python3.8/socketserver.py", line 747, in __init__
    self.handle()
  File "/data1/wyz/online/LEONForPostgres/leon_server.py", line 269, in handle
    if self.handle_json(json.loads(json_msg)):
  File "/data1/wyz/online/LEONForPostgres/leon_server.py", line 285, in handle_json
    result = self.server.leon_model.predict_plan(self.__messages)
  File "/data1/wyz/online/LEONForPostgres/leon_server.py", line 199, in predict_plan
    data[self.curr_file].append(all_time)
KeyError: '33c'
----------------------------------------
----------------------------------------
Exception happened during processing of request from ('127.0.0.1', 51588)
Traceback (most recent call last):
  File "/data1/wyz/miniconda3/envs/unlearning/lib/python3.8/socketserver.py", line 316, in _handle_request_noblock
    self.process_request(request, client_address)
  File "/data1/wyz/miniconda3/envs/unlearning/lib/python3.8/socketserver.py", line 347, in process_request
    self.finish_request(request, client_address)
  File "/data1/wyz/miniconda3/envs/unlearning/lib/python3.8/socketserver.py", line 360, in finish_request
    self.RequestHandlerClass(request, client_address, self)
  File "/data1/wyz/miniconda3/envs/unlearning/lib/python3.8/socketserver.py", line 747, in __init__
    self.handle()
  File "/data1/wyz/online/LEONForPostgres/leon_server.py", line 269, in handle
    if self.handle_json(json.loads(json_msg)):
  File "/data1/wyz/online/LEONForPostgres/leon_server.py", line 285, in handle_json
    result = self.server.leon_model.predict_plan(self.__messages)
  File "/data1/wyz/online/LEONForPostgres/leon_server.py", line 199, in predict_plan
    data[self.curr_file].append(all_time)
KeyError: '33c'
----------------------------------------
----------------------------------------
Exception happened during processing of request from ('127.0.0.1', 51598)
Traceback (most recent call last):
  File "/data1/wyz/miniconda3/envs/unlearning/lib/python3.8/socketserver.py", line 316, in _handle_request_noblock
    self.process_request(request, client_address)
  File "/data1/wyz/miniconda3/envs/unlearning/lib/python3.8/socketserver.py", line 347, in process_request
    self.finish_request(request, client_address)
  File "/data1/wyz/miniconda3/envs/unlearning/lib/python3.8/socketserver.py", line 360, in finish_request
    self.RequestHandlerClass(request, client_address, self)
  File "/data1/wyz/miniconda3/envs/unlearning/lib/python3.8/socketserver.py", line 747, in __init__
    self.handle()
  File "/data1/wyz/online/LEONForPostgres/leon_server.py", line 269, in handle
    if self.handle_json(json.loads(json_msg)):
  File "/data1/wyz/online/LEONForPostgres/leon_server.py", line 285, in handle_json
    result = self.server.leon_model.predict_plan(self.__messages)
  File "/data1/wyz/online/LEONForPostgres/leon_server.py", line 199, in predict_plan
    data[self.curr_file].append(all_time)
KeyError: '33c'
----------------------------------------
----------------------------------------
Exception happened during processing of request from ('127.0.0.1', 51600)
Traceback (most recent call last):
  File "/data1/wyz/miniconda3/envs/unlearning/lib/python3.8/socketserver.py", line 316, in _handle_request_noblock
    self.process_request(request, client_address)
  File "/data1/wyz/miniconda3/envs/unlearning/lib/python3.8/socketserver.py", line 347, in process_request
    self.finish_request(request, client_address)
  File "/data1/wyz/miniconda3/envs/unlearning/lib/python3.8/socketserver.py", line 360, in finish_request
    self.RequestHandlerClass(request, client_address, self)
  File "/data1/wyz/miniconda3/envs/unlearning/lib/python3.8/socketserver.py", line 747, in __init__
    self.handle()
  File "/data1/wyz/online/LEONForPostgres/leon_server.py", line 269, in handle
    if self.handle_json(json.loads(json_msg)):
  File "/data1/wyz/online/LEONForPostgres/leon_server.py", line 285, in handle_json
    result = self.server.leon_model.predict_plan(self.__messages)
  File "/data1/wyz/online/LEONForPostgres/leon_server.py", line 199, in predict_plan
    data[self.curr_file].append(all_time)
KeyError: '33c'
----------------------------------------
----------------------------------------
Exception happened during processing of request from ('127.0.0.1', 51608)
Traceback (most recent call last):
  File "/data1/wyz/miniconda3/envs/unlearning/lib/python3.8/socketserver.py", line 316, in _handle_request_noblock
    self.process_request(request, client_address)
  File "/data1/wyz/miniconda3/envs/unlearning/lib/python3.8/socketserver.py", line 347, in process_request
    self.finish_request(request, client_address)
  File "/data1/wyz/miniconda3/envs/unlearning/lib/python3.8/socketserver.py", line 360, in finish_request
    self.RequestHandlerClass(request, client_address, self)
  File "/data1/wyz/miniconda3/envs/unlearning/lib/python3.8/socketserver.py", line 747, in __init__
    self.handle()
  File "/data1/wyz/online/LEONForPostgres/leon_server.py", line 269, in handle
    if self.handle_json(json.loads(json_msg)):
  File "/data1/wyz/online/LEONForPostgres/leon_server.py", line 285, in handle_json
    result = self.server.leon_model.predict_plan(self.__messages)
  File "/data1/wyz/online/LEONForPostgres/leon_server.py", line 199, in predict_plan
    data[self.curr_file].append(all_time)
KeyError: '33c'
----------------------------------------
----------------------------------------
Exception happened during processing of request from ('127.0.0.1', 51616)
Traceback (most recent call last):
  File "/data1/wyz/miniconda3/envs/unlearning/lib/python3.8/socketserver.py", line 316, in _handle_request_noblock
    self.process_request(request, client_address)
  File "/data1/wyz/miniconda3/envs/unlearning/lib/python3.8/socketserver.py", line 347, in process_request
    self.finish_request(request, client_address)
  File "/data1/wyz/miniconda3/envs/unlearning/lib/python3.8/socketserver.py", line 360, in finish_request
    self.RequestHandlerClass(request, client_address, self)
  File "/data1/wyz/miniconda3/envs/unlearning/lib/python3.8/socketserver.py", line 747, in __init__
    self.handle()
  File "/data1/wyz/online/LEONForPostgres/leon_server.py", line 269, in handle
    if self.handle_json(json.loads(json_msg)):
  File "/data1/wyz/online/LEONForPostgres/leon_server.py", line 285, in handle_json
    result = self.server.leon_model.predict_plan(self.__messages)
  File "/data1/wyz/online/LEONForPostgres/leon_server.py", line 199, in predict_plan
    data[self.curr_file].append(all_time)
KeyError: '33c'
----------------------------------------
----------------------------------------
Exception happened during processing of request from ('127.0.0.1', 51618)
Traceback (most recent call last):
  File "/data1/wyz/miniconda3/envs/unlearning/lib/python3.8/socketserver.py", line 316, in _handle_request_noblock
    self.process_request(request, client_address)
  File "/data1/wyz/miniconda3/envs/unlearning/lib/python3.8/socketserver.py", line 347, in process_request
    self.finish_request(request, client_address)
  File "/data1/wyz/miniconda3/envs/unlearning/lib/python3.8/socketserver.py", line 360, in finish_request
    self.RequestHandlerClass(request, client_address, self)
  File "/data1/wyz/miniconda3/envs/unlearning/lib/python3.8/socketserver.py", line 747, in __init__
    self.handle()
  File "/data1/wyz/online/LEONForPostgres/leon_server.py", line 269, in handle
    if self.handle_json(json.loads(json_msg)):
  File "/data1/wyz/online/LEONForPostgres/leon_server.py", line 285, in handle_json
    result = self.server.leon_model.predict_plan(self.__messages)
  File "/data1/wyz/online/LEONForPostgres/leon_server.py", line 199, in predict_plan
    data[self.curr_file].append(all_time)
KeyError: '33c'
----------------------------------------
----------------------------------------
Exception happened during processing of request from ('127.0.0.1', 51626)
Traceback (most recent call last):
  File "/data1/wyz/miniconda3/envs/unlearning/lib/python3.8/socketserver.py", line 316, in _handle_request_noblock
    self.process_request(request, client_address)
  File "/data1/wyz/miniconda3/envs/unlearning/lib/python3.8/socketserver.py", line 347, in process_request
    self.finish_request(request, client_address)
  File "/data1/wyz/miniconda3/envs/unlearning/lib/python3.8/socketserver.py", line 360, in finish_request
    self.RequestHandlerClass(request, client_address, self)
  File "/data1/wyz/miniconda3/envs/unlearning/lib/python3.8/socketserver.py", line 747, in __init__
    self.handle()
  File "/data1/wyz/online/LEONForPostgres/leon_server.py", line 269, in handle
    if self.handle_json(json.loads(json_msg)):
  File "/data1/wyz/online/LEONForPostgres/leon_server.py", line 285, in handle_json
    result = self.server.leon_model.predict_plan(self.__messages)
  File "/data1/wyz/online/LEONForPostgres/leon_server.py", line 199, in predict_plan
    data[self.curr_file].append(all_time)
KeyError: '33c'
----------------------------------------
----------------------------------------
Exception happened during processing of request from ('127.0.0.1', 51632)
Traceback (most recent call last):
  File "/data1/wyz/miniconda3/envs/unlearning/lib/python3.8/socketserver.py", line 316, in _handle_request_noblock
    self.process_request(request, client_address)
  File "/data1/wyz/miniconda3/envs/unlearning/lib/python3.8/socketserver.py", line 347, in process_request
    self.finish_request(request, client_address)
  File "/data1/wyz/miniconda3/envs/unlearning/lib/python3.8/socketserver.py", line 360, in finish_request
    self.RequestHandlerClass(request, client_address, self)
  File "/data1/wyz/miniconda3/envs/unlearning/lib/python3.8/socketserver.py", line 747, in __init__
    self.handle()
  File "/data1/wyz/online/LEONForPostgres/leon_server.py", line 269, in handle
    if self.handle_json(json.loads(json_msg)):
  File "/data1/wyz/online/LEONForPostgres/leon_server.py", line 285, in handle_json
    result = self.server.leon_model.predict_plan(self.__messages)
  File "/data1/wyz/online/LEONForPostgres/leon_server.py", line 199, in predict_plan
    data[self.curr_file].append(all_time)
KeyError: '33c'
----------------------------------------
----------------------------------------
Exception happened during processing of request from ('127.0.0.1', 51648)
Traceback (most recent call last):
  File "/data1/wyz/miniconda3/envs/unlearning/lib/python3.8/socketserver.py", line 316, in _handle_request_noblock
    self.process_request(request, client_address)
  File "/data1/wyz/miniconda3/envs/unlearning/lib/python3.8/socketserver.py", line 347, in process_request
    self.finish_request(request, client_address)
  File "/data1/wyz/miniconda3/envs/unlearning/lib/python3.8/socketserver.py", line 360, in finish_request
    self.RequestHandlerClass(request, client_address, self)
  File "/data1/wyz/miniconda3/envs/unlearning/lib/python3.8/socketserver.py", line 747, in __init__
    self.handle()
  File "/data1/wyz/online/LEONForPostgres/leon_server.py", line 269, in handle
    if self.handle_json(json.loads(json_msg)):
  File "/data1/wyz/online/LEONForPostgres/leon_server.py", line 285, in handle_json
    result = self.server.leon_model.predict_plan(self.__messages)
  File "/data1/wyz/online/LEONForPostgres/leon_server.py", line 199, in predict_plan
    data[self.curr_file].append(all_time)
KeyError: '33c'
----------------------------------------
----------------------------------------
Exception happened during processing of request from ('127.0.0.1', 51652)
Traceback (most recent call last):
  File "/data1/wyz/miniconda3/envs/unlearning/lib/python3.8/socketserver.py", line 316, in _handle_request_noblock
    self.process_request(request, client_address)
  File "/data1/wyz/miniconda3/envs/unlearning/lib/python3.8/socketserver.py", line 347, in process_request
    self.finish_request(request, client_address)
  File "/data1/wyz/miniconda3/envs/unlearning/lib/python3.8/socketserver.py", line 360, in finish_request
    self.RequestHandlerClass(request, client_address, self)
  File "/data1/wyz/miniconda3/envs/unlearning/lib/python3.8/socketserver.py", line 747, in __init__
    self.handle()
  File "/data1/wyz/online/LEONForPostgres/leon_server.py", line 269, in handle
    if self.handle_json(json.loads(json_msg)):
  File "/data1/wyz/online/LEONForPostgres/leon_server.py", line 285, in handle_json
    result = self.server.leon_model.predict_plan(self.__messages)
  File "/data1/wyz/online/LEONForPostgres/leon_server.py", line 199, in predict_plan
    data[self.curr_file].append(all_time)
KeyError: '33c'
----------------------------------------
----------------------------------------
Exception happened during processing of request from ('127.0.0.1', 51660)
Traceback (most recent call last):
  File "/data1/wyz/miniconda3/envs/unlearning/lib/python3.8/socketserver.py", line 316, in _handle_request_noblock
    self.process_request(request, client_address)
  File "/data1/wyz/miniconda3/envs/unlearning/lib/python3.8/socketserver.py", line 347, in process_request
    self.finish_request(request, client_address)
  File "/data1/wyz/miniconda3/envs/unlearning/lib/python3.8/socketserver.py", line 360, in finish_request
    self.RequestHandlerClass(request, client_address, self)
  File "/data1/wyz/miniconda3/envs/unlearning/lib/python3.8/socketserver.py", line 747, in __init__
    self.handle()
  File "/data1/wyz/online/LEONForPostgres/leon_server.py", line 269, in handle
    if self.handle_json(json.loads(json_msg)):
  File "/data1/wyz/online/LEONForPostgres/leon_server.py", line 285, in handle_json
    result = self.server.leon_model.predict_plan(self.__messages)
  File "/data1/wyz/online/LEONForPostgres/leon_server.py", line 199, in predict_plan
    data[self.curr_file].append(all_time)
KeyError: '33c'
----------------------------------------
----------------------------------------
Exception happened during processing of request from ('127.0.0.1', 51672)
Traceback (most recent call last):
  File "/data1/wyz/miniconda3/envs/unlearning/lib/python3.8/socketserver.py", line 316, in _handle_request_noblock
    self.process_request(request, client_address)
  File "/data1/wyz/miniconda3/envs/unlearning/lib/python3.8/socketserver.py", line 347, in process_request
    self.finish_request(request, client_address)
  File "/data1/wyz/miniconda3/envs/unlearning/lib/python3.8/socketserver.py", line 360, in finish_request
    self.RequestHandlerClass(request, client_address, self)
  File "/data1/wyz/miniconda3/envs/unlearning/lib/python3.8/socketserver.py", line 747, in __init__
    self.handle()
  File "/data1/wyz/online/LEONForPostgres/leon_server.py", line 269, in handle
    if self.handle_json(json.loads(json_msg)):
  File "/data1/wyz/online/LEONForPostgres/leon_server.py", line 285, in handle_json
    result = self.server.leon_model.predict_plan(self.__messages)
  File "/data1/wyz/online/LEONForPostgres/leon_server.py", line 199, in predict_plan
    data[self.curr_file].append(all_time)
KeyError: '33c'
----------------------------------------
----------------------------------------
Exception happened during processing of request from ('127.0.0.1', 51676)
Traceback (most recent call last):
  File "/data1/wyz/miniconda3/envs/unlearning/lib/python3.8/socketserver.py", line 316, in _handle_request_noblock
    self.process_request(request, client_address)
  File "/data1/wyz/miniconda3/envs/unlearning/lib/python3.8/socketserver.py", line 347, in process_request
    self.finish_request(request, client_address)
  File "/data1/wyz/miniconda3/envs/unlearning/lib/python3.8/socketserver.py", line 360, in finish_request
    self.RequestHandlerClass(request, client_address, self)
  File "/data1/wyz/miniconda3/envs/unlearning/lib/python3.8/socketserver.py", line 747, in __init__
    self.handle()
  File "/data1/wyz/online/LEONForPostgres/leon_server.py", line 269, in handle
    if self.handle_json(json.loads(json_msg)):
  File "/data1/wyz/online/LEONForPostgres/leon_server.py", line 285, in handle_json
    result = self.server.leon_model.predict_plan(self.__messages)
  File "/data1/wyz/online/LEONForPostgres/leon_server.py", line 199, in predict_plan
    data[self.curr_file].append(all_time)
KeyError: '33c'
----------------------------------------
----------------------------------------
Exception happened during processing of request from ('127.0.0.1', 51684)
Traceback (most recent call last):
  File "/data1/wyz/miniconda3/envs/unlearning/lib/python3.8/socketserver.py", line 316, in _handle_request_noblock
    self.process_request(request, client_address)
  File "/data1/wyz/miniconda3/envs/unlearning/lib/python3.8/socketserver.py", line 347, in process_request
    self.finish_request(request, client_address)
  File "/data1/wyz/miniconda3/envs/unlearning/lib/python3.8/socketserver.py", line 360, in finish_request
    self.RequestHandlerClass(request, client_address, self)
  File "/data1/wyz/miniconda3/envs/unlearning/lib/python3.8/socketserver.py", line 747, in __init__
    self.handle()
  File "/data1/wyz/online/LEONForPostgres/leon_server.py", line 269, in handle
    if self.handle_json(json.loads(json_msg)):
  File "/data1/wyz/online/LEONForPostgres/leon_server.py", line 285, in handle_json
    result = self.server.leon_model.predict_plan(self.__messages)
  File "/data1/wyz/online/LEONForPostgres/leon_server.py", line 199, in predict_plan
    data[self.curr_file].append(all_time)
KeyError: '33c'
----------------------------------------
----------------------------------------
Exception happened during processing of request from ('127.0.0.1', 51688)
Traceback (most recent call last):
  File "/data1/wyz/miniconda3/envs/unlearning/lib/python3.8/socketserver.py", line 316, in _handle_request_noblock
    self.process_request(request, client_address)
  File "/data1/wyz/miniconda3/envs/unlearning/lib/python3.8/socketserver.py", line 347, in process_request
    self.finish_request(request, client_address)
  File "/data1/wyz/miniconda3/envs/unlearning/lib/python3.8/socketserver.py", line 360, in finish_request
    self.RequestHandlerClass(request, client_address, self)
  File "/data1/wyz/miniconda3/envs/unlearning/lib/python3.8/socketserver.py", line 747, in __init__
    self.handle()
  File "/data1/wyz/online/LEONForPostgres/leon_server.py", line 269, in handle
    if self.handle_json(json.loads(json_msg)):
  File "/data1/wyz/online/LEONForPostgres/leon_server.py", line 285, in handle_json
    result = self.server.leon_model.predict_plan(self.__messages)
  File "/data1/wyz/online/LEONForPostgres/leon_server.py", line 199, in predict_plan
    data[self.curr_file].append(all_time)
KeyError: '33c'
----------------------------------------
----------------------------------------
Exception happened during processing of request from ('127.0.0.1', 51698)
Traceback (most recent call last):
  File "/data1/wyz/miniconda3/envs/unlearning/lib/python3.8/socketserver.py", line 316, in _handle_request_noblock
    self.process_request(request, client_address)
  File "/data1/wyz/miniconda3/envs/unlearning/lib/python3.8/socketserver.py", line 347, in process_request
    self.finish_request(request, client_address)
  File "/data1/wyz/miniconda3/envs/unlearning/lib/python3.8/socketserver.py", line 360, in finish_request
    self.RequestHandlerClass(request, client_address, self)
  File "/data1/wyz/miniconda3/envs/unlearning/lib/python3.8/socketserver.py", line 747, in __init__
    self.handle()
  File "/data1/wyz/online/LEONForPostgres/leon_server.py", line 269, in handle
    if self.handle_json(json.loads(json_msg)):
  File "/data1/wyz/online/LEONForPostgres/leon_server.py", line 285, in handle_json
    result = self.server.leon_model.predict_plan(self.__messages)
  File "/data1/wyz/online/LEONForPostgres/leon_server.py", line 199, in predict_plan
    data[self.curr_file].append(all_time)
KeyError: '33c'
----------------------------------------
----------------------------------------
Exception happened during processing of request from ('127.0.0.1', 51710)
Traceback (most recent call last):
  File "/data1/wyz/miniconda3/envs/unlearning/lib/python3.8/socketserver.py", line 316, in _handle_request_noblock
    self.process_request(request, client_address)
  File "/data1/wyz/miniconda3/envs/unlearning/lib/python3.8/socketserver.py", line 347, in process_request
    self.finish_request(request, client_address)
  File "/data1/wyz/miniconda3/envs/unlearning/lib/python3.8/socketserver.py", line 360, in finish_request
    self.RequestHandlerClass(request, client_address, self)
  File "/data1/wyz/miniconda3/envs/unlearning/lib/python3.8/socketserver.py", line 747, in __init__
    self.handle()
  File "/data1/wyz/online/LEONForPostgres/leon_server.py", line 269, in handle
    if self.handle_json(json.loads(json_msg)):
  File "/data1/wyz/online/LEONForPostgres/leon_server.py", line 285, in handle_json
    result = self.server.leon_model.predict_plan(self.__messages)
  File "/data1/wyz/online/LEONForPostgres/leon_server.py", line 199, in predict_plan
    data[self.curr_file].append(all_time)
KeyError: '33c'
----------------------------------------
----------------------------------------
Exception happened during processing of request from ('127.0.0.1', 51720)
Traceback (most recent call last):
  File "/data1/wyz/miniconda3/envs/unlearning/lib/python3.8/socketserver.py", line 316, in _handle_request_noblock
    self.process_request(request, client_address)
  File "/data1/wyz/miniconda3/envs/unlearning/lib/python3.8/socketserver.py", line 347, in process_request
    self.finish_request(request, client_address)
  File "/data1/wyz/miniconda3/envs/unlearning/lib/python3.8/socketserver.py", line 360, in finish_request
    self.RequestHandlerClass(request, client_address, self)
  File "/data1/wyz/miniconda3/envs/unlearning/lib/python3.8/socketserver.py", line 747, in __init__
    self.handle()
  File "/data1/wyz/online/LEONForPostgres/leon_server.py", line 269, in handle
    if self.handle_json(json.loads(json_msg)):
  File "/data1/wyz/online/LEONForPostgres/leon_server.py", line 285, in handle_json
    result = self.server.leon_model.predict_plan(self.__messages)
  File "/data1/wyz/online/LEONForPostgres/leon_server.py", line 199, in predict_plan
    data[self.curr_file].append(all_time)
KeyError: '33c'
----------------------------------------
Process Process-1:
Traceback (most recent call last):
  File "/data1/wyz/miniconda3/envs/unlearning/lib/python3.8/multiprocessing/process.py", line 315, in _bootstrap
    self.run()
  File "/data1/wyz/miniconda3/envs/unlearning/lib/python3.8/multiprocessing/process.py", line 108, in run
    self._target(*self._args, **self._kwargs)
  File "/data1/wyz/online/LEONForPostgres/leon_server.py", line 307, in start_server
    server.serve_forever()
  File "/data1/wyz/miniconda3/envs/unlearning/lib/python3.8/socketserver.py", line 232, in serve_forever
    ready = selector.select(poll_interval)
  File "/data1/wyz/miniconda3/envs/unlearning/lib/python3.8/selectors.py", line 415, in select
    fd_event_list = self._selector.poll(timeout)
